<?xml version="1.0"?>
<robot xmlns:xacro="http://www.ros.org/wiki/xacro">

  <xacro:macro name="wheel" params="prefix x y wheel_radius wheel_width">
    <link name="wheel_${prefix}">
      <visual>
        <geometry>
          <cylinder radius="${wheel_radius}" length="${wheel_width}"/>
        </geometry>
        <origin xyz="0 0 0" rpy="1.5708 0 0"/>
        <material name="black">
          <color rgba="0.1 0.1 0.1 1"/>
        </material>
      </visual>

      <collision>
        <geometry>
          <cylinder radius="${wheel_radius}" length="${wheel_width}"/>
        </geometry>
        <origin xyz="0 0 0" rpy="1.5708 0 0"/>
      </collision>

      <inertial>
        <mass value="0.15"/>
        <inertia ixx="0.001" ixy="0" ixz="0"
                 iyy="0.001" iyz="0" izz="0.001"/>
      </inertial>


    </link>

    <joint name="joint_${prefix}" type="continuous">
      <parent link="base_link"/>
      <child link="wheel_${prefix}"/>
      <origin xyz="${x} ${y} ${wheel_radius}" rpy="0 0 0"/>
      <axis xyz="0 1 0"/>
    </joint>

    <gazebo reference="wheel_${prefix}">
        <mu1>20.0</mu1>
        <mu2>20.0</mu2>
        <kp>1000000.0</kp>
        <kd>1.0</kd>
        <material>Gazebo/Black</material>
    </gazebo>
  </xacro:macro>

</robot>